<mujoco model="GEN3_URDF_V12">
    <compiler angle="radian" />
    <size njmax="500" nconmax="100" />
    <asset>
        <mesh name="base_link" file="meshes/base_link.STL" />
        <mesh name="shoulder_link" file="meshes/shoulder_link.STL" />
        <mesh name="half_arm_1_link" file="meshes/half_arm_1_link.STL" />
        <mesh name="half_arm_2_link" file="meshes/half_arm_2_link.STL" />
        <mesh name="forearm_link" file="meshes/forearm_link.STL" />
        <mesh name="spherical_wrist_1_link" file="meshes/spherical_wrist_1_link.STL" />
        <mesh name="spherical_wrist_2_link" file="meshes/spherical_wrist_2_link.STL" />
        <mesh name="bracelet_with_vision_link" file="meshes/bracelet_with_vision_link.STL" />
    </asset>
    <worldbody>
        <geom class="viz" type="mesh" rgba="0.75294 0.75294 0.75294 1" mesh="base_link" />
        <body name="Shoulder_Link" pos="0 0 0.15643" quat="-3.67321e-06 1 0 0">
            <inertial pos="-2.3e-05 -0.010364 -0.07336" quat="0.707051 0.0451246 -0.0453544 0.704263" mass="1.3773" diaginertia="0.00488868 0.00457 0.00135132" />
            <joint name="Actuator1" pos="0 0 0" axis="0 0 1" damping="3" frictionloss="5.5"/>
            <geom class="viz" type="mesh" rgba="0.75294 0.75294 0.75294 1" mesh="shoulder_link" />
            <body name="HalfArm1_Link" pos="0 0.005375 -0.12838" quat="0.707105 0.707108 0 0">
                <inertial pos="-4.4e-05 -0.09958 -0.013278" quat="0.482348 0.516286 -0.516862 0.483366" mass="1.1636" diaginertia="0.0113017 0.011088 0.00102532" />
                <joint name="Actuator2" pos="0 0 0" axis="0 0 1" limited="true" range="-2.41 2.41" damping="3" frictionloss="5.5" />
                <geom class="viz" type="mesh" rgba="0.75294 0.75294 0.75294 1" mesh="half_arm_1_link" />
                <body name="HalfArm2_Link" pos="0 -0.21038 -0.006375" quat="0.707105 -0.707108 0 0">
                    <inertial pos="-4.4e-05 -0.006641 -0.117892" quat="0.706144 0.0213722 -0.0209128 0.707437" mass="1.1636" diaginertia="0.0111633 0.010932 0.00100671" />
                    <joint name="Actuator3" pos="0 0 0" axis="0 0 1" damping="3" frictionloss="5.5"/>
                    <geom class="viz" type="mesh" rgba="0.75294 0.75294 0.75294 1" mesh="half_arm_2_link" />
                    <body name="ForeArm_Link" pos="0 0.006375 -0.21038" quat="0.707105 0.707108 0 0">
                        <inertial pos="-1.8e-05 -0.075478 -0.015006" quat="0.483678 0.515961 -0.515859 0.483455" mass="0.9302" diaginertia="0.00834839 0.008147 0.000598606" />
                        <joint name="Actuator4" pos="0 0 0" axis="0 0 1" limited="true" range="-2.66 2.66" damping="3" frictionloss="5.5" />
                        <geom class="viz" type="mesh" rgba="0.75294 0.75294 0.75294 1" mesh="forearm_link" />
                        <body name="SphericalWrist1_Link" pos="0 -0.20843 -0.006375" quat="0.707105 -0.707108 0 0">
                            <inertial pos="1e-06 -0.009432 -0.063883" quat="0.703558 0.0707492 -0.0707492 0.703558" mass="0.6781" diaginertia="0.00165901 0.001596 0.000346988" />
                            <joint name="Actuator5" pos="0 0 0" axis="0 0 1" damping="3" frictionloss="5.5"/>
                            <geom class="viz" type="mesh" rgba="0.75294 0.75294 0.75294 1" mesh="spherical_wrist_1_link" />
                            <body name="SphericalWrist2_Link" pos="0 0.00017505 -0.10593" quat="0.707105 0.707108 0 0">
                                <inertial pos="1e-06 -0.045483 -0.00965" quat="0.44426 0.550121 -0.550121 0.44426" mass="0.6781" diaginertia="0.00170087 0.001641 0.00035013" />
                                <joint name="Actuator6" pos="0 0 0" axis="0 0 1" limited="true" range="-2.23 2.23" damping="3" frictionloss="5.5" />
                                <geom class="viz" type="mesh" rgba="0.75294 0.75294 0.75294 1" mesh="spherical_wrist_2_link" />
                                <body name="Bracelet_Link" pos="0 -0.10593 -0.00017505" quat="0.707105 -0.707108 0 0">
                                    <inertial pos="-0.000281 -0.011402 -0.029798" quat="0.601961 0.40663 -0.381169 0.571843" mass="0.5006" diaginertia="0.000657515 0.000586793 0.000320693" />
                                    <joint name="Actuator7" pos="0 0 0" axis="0 0 1" damping="3" frictionloss="5.5"/>
                                    <geom class="viz" type="mesh" rgba="0.75294 0.75294 0.75294 1" mesh="bracelet_with_vision_link" />
                                </body>
                            </body>
                        </body>
                    </body>
                </body>
            </body>
        </body>
    </worldbody>
    <actuator>    
        <position name="Actuator1" joint="Actuator1" kp="400"/>
        <position name="Actuator2" joint="Actuator2" kp="400"/>
        <position name="Actuator3" joint="Actuator3" kp="400"/>
        <position name="Actuator4" joint="Actuator4" kp="400"/>
        <position name="Actuator5" joint="Actuator5" kp="400"/>
        <position name="Actuator6" joint="Actuator6" kp="400"/>
        <position name="Actuator7" joint="Actuator7" kp="400"/>

        <!-- <velocity name="Actuator1" joint="Actuator1" kv="20"/>
        <velocity name="Actuator2" joint="Actuator2" kv="20"/>
        <velocity name="Actuator3" joint="Actuator3" kv="20"/>
        <velocity name="Actuator4" joint="Actuator4" kv="20"/>
        <velocity name="Actuator5" joint="Actuator5" kv="20"/>
        <velocity name="Actuator6" joint="Actuator6" kv="20"/>
        <velocity name="Actuator7" joint="Actuator7" kv="20"/> -->
    </actuator>
</mujoco>
