<mujoco model="GEN3-6DOF_VISION_URDF_ARM_V01">
    <compiler angle="radian" />
    <size njmax="500" nconmax="100" />
    
    <!-- 이 부분 추가 -->
    <visual>
        <headlight ambient=".4 .4 .4" diffuse=".8 .8 .8" specular="0.1 0.1 0.1"/>
        <rgba haze=".3 .3 .3 1"/>
    </visual>
    
    <asset>
        <mesh name="base_link" file="../meshes/base_link.STL" />
        <mesh name="shoulder_link" file="../meshes/shoulder_link.STL" />
        <mesh name="bicep_link" file="../meshes/bicep_link.STL" />
        <mesh name="forearm_link" file="../meshes/forearm_link.STL" />
        <mesh name="spherical_wrist_1_link" file="../meshes/spherical_wrist_1_link.STL" />
        <mesh name="spherical_wrist_2_link" file="../meshes/spherical_wrist_2_link.STL" />
        <mesh name="bracelet_with_vision_link" file="../meshes/bracelet_with_vision_link.STL" />
        
        <!-- 이 부분 추가 -->
        <texture type="skybox" builtin="gradient" rgb1=".4 .6 .8" rgb2="0 0 0" width="512" height="512"/>
        
    </asset>
    <worldbody>
        <geom type="mesh" rgba="0.75294 0.75294 0.75294 1" mesh="base_link" />
        <body name="Shoulder_Link" pos="0 0 0.15643" quat="-3.67321e-06 -1 0 0">
            <inertial pos="-2.3e-05 -0.010364 -0.07336" quat="0.707051 0.0451246 -0.0453544 0.704263" mass="1.377" diaginertia="0.00488868 0.00457 0.00135132" />
            <joint name="Actuator1" pos="0 0 0" axis="0 0 1" limited="true" range="-3.14 3.14" damping="3" frictionloss="5.5" />
            <geom type="mesh" rgba="0.75294 0.75294 0.75294 1" mesh="shoulder_link" />
            <body name="Bicep_Link" pos="0 0.005375 -0.12838" quat="0.707105 0.707108 0 0">
                <inertial pos="3.5e-05 -0.208207 -0.01889" quat="0.499531 0.50049 -0.500566 0.499411" mass="1.262" diaginertia="0.0471882 0.046752 0.000849791" />
                <joint name="Actuator2" pos="0 0 0" axis="0 0 1" limited="true" range="-2.41 2.41" damping="3" frictionloss="5.5" />
                <geom type="mesh" rgba="0.75294 0.75294 0.75294 1" mesh="bicep_link" />
                <body name="ForeArm_Link" pos="0 -0.41 0" quat="-3.67321e-06 1 0 0">
                    <inertial pos="1.8e-05 0.076168 -0.01397" quat="0.513497 0.485985 -0.486188 0.513577" mass="0.93" diaginertia="0.00848774 0.008292 0.000604256" />
                    <joint name="Actuator3" pos="0 0 0" axis="0 0 1" limited="true" range="-2.66 2.66" damping="3" frictionloss="5.5"/>
                    <geom type="mesh" rgba="0.75294 0.75294 0.75294 1" mesh="forearm_link" />
                    <body name="SphericalWrist1_Link" pos="0 0.20843 -0.006375" quat="0.707105 0.707108 0 0">
                        <inertial pos="-1e-06 0.008486 -0.062937" quat="0.704382 -0.062019 0.062019 0.704382" mass="0.6781" diaginertia="0.00170753 0.001645 0.000347472" />
                        <joint name="Actuator4" pos="0 0 0" axis="0 0 1" limited="true" range="-3.14 3.14" damping="3" frictionloss="5.5"/>
                        <geom type="mesh" rgba="0.75294 0.75294 0.75294 1" mesh="spherical_wrist_1_link" />
                        <body name="SphericalWrist2_Link" pos="0 -0.00017505 -0.10593" quat="0.707105 -0.707108 0 0">
                            <inertial pos="-1e-06 0.046429 -0.008704" quat="0.5446 0.451011 -0.451011 0.5446" mass="0.678" diaginertia="0.00174437 0.001685 0.000351632" />
                            <joint name="Actuator5" pos="0 0 0" axis="0 0 1" limited="true" range="-2.23 2.23" damping="3" frictionloss="5.5"/>
                            <geom type="mesh" rgba="0.75294 0.75294 0.75294 1" mesh="spherical_wrist_2_link" />
                            <body name="Bracelet_Link" pos="0 0.10593 -0.00017505" quat="0.707105 0.707108 0 0">
                                <inertial pos="0.000281 0.011402 -0.029798" quat="0.394358 0.596779 -0.577293 0.393789" mass="0.5" diaginertia="0.000657336 0.000587019 0.000320645" />
                                <joint name="Actuator6" pos="0 0 0" axis="0 0 1" limited="true" range="-3.14 3.14" damping="3" frictionloss="5.5"/>
                                <geom type="mesh" rgba="0.75294 0.75294 0.75294 1" mesh="bracelet_with_vision_link" />
                            </body>
                        </body>
                    </body>
                </body>
            </body>
        </body>
    </worldbody>
    <actuator>    
        <position name="Actuator1" joint="Actuator1" />
        <position name="Actuator2" joint="Actuator2" />
        <position name="Actuator3" joint="Actuator3" />
        <position name="Actuator4" joint="Actuator4" />
        <position name="Actuator5" joint="Actuator5" />
        <position name="Actuator6" joint="Actuator6" />        

        <!-- <velocity name="Actuator1" joint="Actuator1" kv="20"/>
        <velocity name="Actuator2" joint="Actuator2" kv="20"/>
        <velocity name="Actuator3" joint="Actuator3" kv="20"/>
        <velocity name="Actuator4" joint="Actuator4" kv="20"/>
        <velocity name="Actuator5" joint="Actuator5" kv="20"/>
        <velocity name="Actuator6" joint="Actuator6" kv="20"/> -->       
    </actuator>
</mujoco>
